input.txt
NO,SECCODE,BUYSELL,TIME,ORDERNO,ACTION,PRICE,VOLUME,TRADENO,TRADEPRICE
1,EUR_RUB__TOM,B,100000053255,1,1,76.015,3000000,,
2,EUR_RUB__TOM,S,100000053274,2,1,76.235,3000000,,
3,GBPRUB_TOM,B,100000085872,3,1,83,1000,,
4,USD000UTSTOM,B,100000086472,4,1,63.1775,9000,,
5,USD000UTSTOM,B,100000100091,5,1,59.1,1000,,
6,EUR_RUB__TOM,S,100000103318,6,1,76.565,3000000,,
7,USD000UTSTOM,B,100000110416,7,1,61.6,1000,,
8,USD000UTSTOM,B,100000112461,8,1,63.15,26000,,
9,EUR_RUB__TOM,B,100000118302,9,1,76.035,3000000,,
10,EUR_RUB__TOM,B,100000118350,1,0,76.015,3000000,,
11,USD000UTSTOM,S,100000127340,10,1,66,1000,,
12,USD000UTSTOM,S,100000127371,11,1,66.91,18000,,
13,USD000UTSTOM,S,100000129192,12,1,66,1000,,
14,USD000UTSTOM,S,100000129491,13,1,65.78,1000,,
15,USD000UTSTOM,S,100000130938,14,1,66,1000,,
16,USD000UTSTOM,S,100000131649,15,1,66.0075,1000,,
17,USD000UTSTOM,S,100000132598,16,1,66.19,1000,,
18,USD000UTSTOM,S,100000133843,17,1,65.5,1000,,
19,USD000UTSTOM,S,100000134383,18,1,65.88,50000,,
20,USD000UTSTOM,S,100000136168,19,1,67,1000,,
21,USD000UTSTOM,S,100000136213,20,1,65.11,10000,,
22,USD000UTSTOM,S,100000137910,21,1,66.91,1000,,
23,USD000UTSTOM,S,100000138390,22,1,65.5,35000,,
24,USD000UTSTOM,S,100000139652,23,1,65.9625,1000,,
25,USD000UTSTOM,S,100000140589,24,1,65.15,1000,,
26,USD000UTSTOM,S,100000141414,25,1,65.9,18000,,
27,USD000UTSTOM,S,100000142645,26,1,65,1000,,
28,USD000UTSTOM,B,100000143268,27,1,63.21,40000,,
29,USD000UTSTOM,S,100000143487,28,1,65.285,1000,,
30,USD000UTSTOM,S,100000143650,29,1,63.41,40000,,
31,USD000UTSTOM,B,100000143948,30,1,63.21,40000,,
32,USD000UTSTOM,S,100000144237,31,1,63.41,40000,,
33,USD000UTSTOM,B,100000144532,32,1,63.21,40000,,
34,USD000UTSTOM,S,100000144767,33,1,66.88,2000,,
35,USD000UTSTOM,S,100000144814,34,1,63.41,40000,,
36,USD000UTSTOM,B,100000145090,35,1,63.21,40000,,
37,USD000UTSTOM,S,100000145248,36,1,65,1000,,
38,USD000UTSTOM,S,100000145361,37,1,63.41,40000,,
39,USD000UTSTOM,B,100000145633,38,1,63.21,40000,,
40,USD000UTSTOM,S,100000145900,39,1,63.41,40000,,
41,USD000UTSTOM,B,100000146195,40,1,63.21,40000,,
42,USD000UTSTOM,S,100000146470,41,1,63.41,40000,,
43,USD000UTSTOM,B,100000146770,42,1,63.21,40000,,
44,USD000UTSTOM,S,100000147014,43,1,65,1000,,
45,USD000UTSTOM,S,100000147028,44,1,66.995,1000,,
46,USD000UTSTOM,B,100000148818,45,1,60.54,10000,,
47,USD000UTSTOM,S,100000149282,46,1,65,2000,,
48,EUR_RUB__TOM,B,100000150280,47,1,76.065,1000000,,
49,USD000UTSTOM,B,100000150293,48,1,63.335,100000,,
50,USD000UTSTOM,B,100000150301,49,1,63.325,100000,,
51,EUR_RUB__TOM,S,100000150308,50,1,76.195,1000000,,
52,EURUSD000TOM,S,100000150319,51,1,1.20165,1000000,,
53,USD000UTSTOM,S,100000150707,52,1,63.42,100000,,
54,USD000UTSTOM,S,100000150783,53,1,65.3,3000,,
55,CNYRUB_TOM,B,100000151029,54,1,9.952,500000,,
56,CNYRUB_TOM,S,100000151306,55,1,9.986,500000,,
57,USD000UTSTOM,S,100000151457,56,1,65.5,1000,,
58,CNYRUB_TOM,B,100000151569,57,1,9.9546,3000000,,
59,CNYRUB_TOM,S,100000151818,58,1,9.984,3000000,,
60,USD000UTSTOM,S,100000152568,59,1,66.0125,1000,,
61,EURUSD000TOM,B,100000153199,60,1,1.20095,1000000,,
62,USD000UTSTOM,S,100000153676,61,1,66,1000,,
63,USD000UTSTOM,S,100000154347,62,1,64.4,30000,,
64,USD000UTSTOM,S,100000154617,63,1,63.41,40000,,
65,USD000UTSTOM,B,100000154923,64,1,63.21,40000,,
66,USD000UTSTOM,S,100000155210,65,1,63.41,40000,,
67,USD000UTSTOM,B,100000155510,66,1,63.21,40000,,
68,USD000UTSTOM,S,100000155800,67,1,63.41,40000,,
69,USD000UTSTOM,S,100000155930,68,1,66,2000,,
70,USD000UTSTOM,B,100000156083,69,1,63.21,40000,,
71,USD000UTSTOM,S,100000156099,70,1,66.4725,1000,,
72,USD000UTSTOM,S,100000156359,71,1,63.41,40000,,
73,USD000UTSTOM,S,100000157951,72,1,64.5475,1000,,
74,USD000UTSTOM,S,100000158171,73,1,65,4000,,
75,USD000UTSTOM,S,100000159741,74,1,64.795,1000,,
76,USD000UTSTOM,S,100000160699,75,1,66,1000,,
77,USD000UTSTOM,S,100000161547,76,1,63.925,1000,,
78,USD000UTSTOM,S,100000162808,77,1,65,3000,,
79,USD000UTSTOM,S,100000163338,78,1,64.5775,2000,,
80,USD000UTSTOM,S,100000164957,79,1,64,1000,,
81,USD000UTSTOM,S,100000164986,80,1,64.9925,1000,,
82,USD000UTSTOM,S,100000166673,81,1,66.5975,1000,,
83,USD000UTSTOM,S,100000166983,82,1,66.66,20000,,
84,USD000UTSTOM,S,100000168485,83,1,66.9975,1000,,
85,EUR_RUB__TOM,B,100000169014,84,1,75.9,3000000,,
86,USD000UTSTOM,S,100000169223,85,1,66.5,5000,,
87,USD000UTSTOM,S,100000170177,86,1,63.2,1000,,
88,USD000UTSTOM,B,100000170177,48,2,63.335,1000,168009383,63.335
89,USD000UTSTOM,S,100000170177,86,2,63.2,1000,168009383,63.335
90,USD000UTSTOM,S,100000171359,87,1,64.86,1000,,
91,USD000UTSTOM,B,100000172220,88,1,60.2,10000,,
92,USD000UTSTOM,S,100000173515,89,1,64,1000,,
93,USD000UTSTOM,B,100000174031,90,1,60.56,5000,,
94,USD000UTSTOM,S,100000175582,91,1,65,1000,,
95,USD000UTSTOM,S,100000175744,92,1,64.7975,1000,,
96,USD000UTSTOM,S,100000177567,93,1,65.7,4000,,
97,USD000UTSTOM,S,100000177735,94,1,65,1000,,
98,USD000UTSTOM,S,100000179309,95,1,67.05,9000,,
99,USD000UTSTOM,S,100000179949,96,1,64.99,1000,,
100,USD000UTSTOM,S,100000181275,97,1,65.3775,15000,,
101,USD000UTSTOM,S,100000182127,98,1,65,1000,,
102,USD000UTSTOM,B,100000182997,99,1,59,3000,,
103,USD000UTSTOM,S,100000184277,100,1,64.7,1000,,
104,USD000UTSTOM,B,100000184796,101,1,59.2,1000,,
105,USD000UTSTOM,S,100000186438,102,1,63.5,1000,,
106,USD000UTSTOM,B,100000186634,103,1,59.1,1000,,
107,USD000UTSTOM,B,100000188615,104,1,58.5,1000,,
108,USD000UTSTOM,S,100000188775,105,1,64.5,5000,,
109,USD000UTSTOM,B,100000190462,106,1,58.7,1000,,
110,USD000UTSTOM,S,100000190997,107,1,64.89,1000,,
111,USD000UTSTOM,B,100000192257,108,1,59.8,6000,,
112,USD000UTSTOM,S,100000193214,109,1,65,1000,,
113,USD000UTSTOM,S,100000194100,110,1,64.08,22000,,
114,USD000UTSTOM,B,100000194243,111,1,63.215,50000,,
115,USD000UTSTOM,S,100000195382,112,1,64.4925,10000,,
116,USD000UTSTOM,S,100000195907,113,1,65,1000,,
117,USD000UTSTOM,S,100000197747,114,1,65,1000,,
118,USD000UTSTOM,B,100000197757,115,1,59.1425,1000,,
119,USD000UTSTOM,S,100000197936,116,1,63.265,6000,,
120,USD000UTSTOM,B,100000197936,48,2,63.335,6000,168009384,63.335
121,USD000UTSTOM,S,100000197936,116,2,63.265,6000,168009384,63.335
122,USD000UTSTOM,B,100000198759,117,1,58.5025,100000,,
123,USD000UTSTOM,S,100000198788,118,1,67.0475,100000,,
124,USD000UTSTOM,S,100000199633,119,1,63.46,1000,,
125,USD000UTSTOM,B,100000200035,120,1,60.33,25000,,
126,EUR_RUB__TOM,B,100000200341,84,0,75.9,3000000,,
127,USD000UTSTOM,B,100000201492,121,1,58.5,5000,,
128,USD000UTSTOM,B,100000202226,122,1,60,1000,,
129,USD000UTSTOM,B,100000203340,123,1,59.555,50000,,
130,USD000UTSTOM,S,100000204443,124,1,63.5,1000,,
131,USD000UTSTOM,B,100000205168,125,1,59.255,50000,,
132,USD000UTSTOM,S,100000206666,126,1,65.02,1000,,
133,USD000UTSTOM,B,100000207027,127,1,59.1225,5000,,
134,USD000UTSTOM,S,100000208862,128,1,63.4425,1000,,
135,USD000UTSTOM,S,100000208905,129,1,64,3000,,
136,USD000UTSTOM,B,100000210722,130,1,60.25,1000,,
137,USD000UTSTOM,B,100000211088,131,1,60.14,1000,,
138,USD000UTSTOM,B,100000212506,132,1,60,1000,,
139,USD000UTSTOM,S,100000213622,133,1,65,5000,,
140,EUR_RUB__TOM,S,100000213676,134,1,78.5,3000,,
141,USD000UTSTOM,B,100000214363,135,1,60.3,1000,,
142,USD000UTSTOM,S,100000215874,136,1,65,10000,,
143,USD000UTSTOM,S,100000216219,137,1,67,1000,,
144,USD000UTSTOM,S,100000218092,138,1,65.12,4000,,
145,USD000UTSTOM,S,100000218135,139,1,64.64,1000,,
146,USD000UTSTOM,S,100000219962,140,1,63.9975,2000,,
147,USD000UTSTOM,S,100000220331,141,1,64.5,1000,,
148,USD000UTSTOM,S,100000221869,142,1,66,1000,,
149,USD000UTSTOM,B,100000223066,143,1,60.555,1000,,
150,USD000UTSTOM,S,100000223675,144,1,65,37000,,
151,USD000UTSTOM,B,100000225336,145,1,60,1000,,
152,USD000UTSTOM,B,100000225475,146,1,60.07,1000,,
153,USD000UTSTOM,S,100000227366,147,1,64,5000,,
154,EUR_RUB__TOM,S,100000227444,148,1,76.2325,200000,,
155,USD000UTSTOM,S,100000227565,149,1,63.8,3000,,
156,USD000UTSTOM,S,100000227991,118,0,67.0475,100000,,
157,USD000UTSTOM,S,100000227991,150,1,66.9925,100000,,
158,USD000UTSTOM,B,100000229170,151,1,60.0075,1000,,
159,USD000UTSTOM,S,100000229825,152,1,66.76,2000,,
