output/task3 output.txt
USD000000TOD
avg by count bid cdf: [0.1838109358259471, 0.39880982842479323, 0.5385820846511891, 0.6694003684689085, 0.7393576562761104, 0.7887272475660981, 0.8353094396096342, 0.8868280366036058, 0.9452597482194003, 0.9999983968834707]
avg by time bid cdf: [0.2676198780184061, 0.4528562426547651, 0.5327213175728038, 0.6606172571944281, 0.6929198479951316, 0.7733953279856778, 0.8250010035015791, 0.861967558013682, 0.9170578434674899, 0.9999999996666734]
avg by count ask cdf: [0.03990103027564722, 0.06831745895419652, 0.311233535172013, 0.3362462876075469, 0.36871515848129605, 0.8459256644734001, 0.9071586245986497, 0.9288728877989066, 0.9394540520638934, 1.0000000000029037]
avg by time ask cdf: [0.02785870142944844, 0.03680000152650824, 0.30249197480795614, 0.3149189355999744, 0.3339672475673917, 0.8771652106399338, 0.9369821188797137, 0.9442219135219903, 0.9491434396355144, 0.9999999999999334]
avg by count: bid distribution vs ask distribution: True
avg by time: bid distribution vs ask distribution: True
bid distributions: avg by count vs avg by time: True
ask distributions: avg by count vs avg by time: True

USD000UTSTOM
avg by count bid cdf: [0.14259094353825197, 0.34564461694976795, 0.4090726777563324, 0.4591058008392391, 0.5137987876869996, 0.6965108565200868, 0.8215866276432596, 0.8784655824975345, 0.9365300843166897, 0.9999991210167238]
avg by time bid cdf: [0.141597028674653, 0.36875938795443963, 0.42334634282413064, 0.47583339343700304, 0.5238691685759066, 0.7121369208848741, 0.8119769771032724, 0.8676880666575397, 0.9234662087734541, 0.9999999975777661]
avg by count ask cdf: [0.30193057336871226, 0.43905914446905964, 0.560214207391387, 0.8510364852838666, 0.9004400295460189, 0.920096142116284, 0.9400683303958512, 0.9515959561547116, 0.989428277345382, 0.9999999999860973]
avg by time ask cdf: [0.308843830687736, 0.4476332941739688, 0.5712183763684483, 0.867784770819434, 0.9143221358025317, 0.9269147971717543, 0.9467685502655202, 0.955204030426108, 0.9924013823874137, 0.9999999999995848]
avg by count: bid distribution vs ask distribution: True
avg by time: bid distribution vs ask distribution: True
bid distributions: avg by count vs avg by time: True
ask distributions: avg by count vs avg by time: True

EUR_RUB__TOD
avg by count bid cdf: [0.14701407859823604, 0.37651218005064413, 0.5749116956294023, 0.6537312740657198, 0.6838147858479033, 0.8469319652909083, 0.9203077162405447, 0.9439040330125565, 0.9729694688168826, 0.9999999999998962]
avg by time bid cdf: [0.2727326214930088, 0.3684489973742199, 0.628651568331787, 0.6471893316080748, 0.653828431331997, 0.9093094483103404, 0.9618126790012028, 0.9718748628642211, 0.9918553447393964, 1.0000000000000042]
avg by count ask cdf: [0.3932133256535559, 0.4969685728728496, 0.6103953447815372, 0.633770306761023, 0.6675994981596226, 0.7859125643341797, 0.8301268061663557, 0.8602657198015996, 0.8962143545299185, 0.9999977067165515]
avg by time ask cdf: [0.8364381139010676, 0.8646268347877071, 0.8987540043862755, 0.9025508842238233, 0.9076144315352282, 0.955892565808403, 0.9620255801590984, 0.9670314336201618, 0.9759474155536195, 0.9999999998074051]
avg by count: bid distribution vs ask distribution: True
avg by time: bid distribution vs ask distribution: False
bid distributions: avg by count vs avg by time: True
ask distributions: avg by count vs avg by time: True

EUR_RUB__TOM
avg by count bid cdf: [0.17496500947732677, 0.3773038363812877, 0.5360824806761133, 0.6494610344639615, 0.6810562725550312, 0.8044818202145491, 0.902480711646655, 0.9281371811668064, 0.9607937910447428, 1.0000000000001128]
avg by time bid cdf: [0.2030187784376332, 0.41073315273772115, 0.5565863290634622, 0.6637346474654874, 0.689653702639024, 0.8198912747275715, 0.9039867073941172, 0.9225630358186261, 0.9592200864005365, 1.000000000000016]
avg by count ask cdf: [0.33080129697639227, 0.4277313451371735, 0.5231595877903366, 0.6044133638253704, 0.6498720823515741, 0.7368281327566405, 0.8307644537718433, 0.8778594830085595, 0.9317369392636152, 0.9999992345088886]
avg by time ask cdf: [0.3958651156667821, 0.49774829580301727, 0.5832772277295797, 0.6461168601474817, 0.6804501329542584, 0.7695536546630051, 0.8374127538992344, 0.8611914574479287, 0.8980444610268604, 0.9999999998370428]
avg by count: bid distribution vs ask distribution: True
avg by time: bid distribution vs ask distribution: True
bid distributions: avg by count vs avg by time: True
ask distributions: avg by count vs avg by time: True

EURUSD000TOD
avg by count bid cdf: [0.9372009127246655, 0.945092366935732, 0.9476289122869743, 0.954777514550486, 0.962846726855279, 0.9655740620109114, 0.967101762483988, 0.9809348706494881, 0.9952110563118662, 1.000000000000782]
avg by time bid cdf: [0.8643164488796645, 0.8660427935715047, 0.8665233787471903, 0.908309871835283, 0.911023984612899, 0.9117859759022117, 0.9121267076255384, 0.9933617433087247, 0.99875708991176, 0.9999999999999959]
avg by count ask cdf: [0.9967330350525067, 0.9992218341545169, 0.9992218341545169, 0.9992218341545169, 0.9992218341545169, 0.9992218341545169, 0.9992218341545169, 0.9992218341545169, 0.999271048874989, 0.9999199330994866]
avg by time ask cdf: [0.9995043040624121, 0.9998819375182252, 0.9998819375182252, 0.9998819375182252, 0.9998819375182252, 0.9998819375182252, 0.9998819375182252, 0.9998819375182252, 0.9998878209701981, 0.9999975527676297]
avg by count: bid distribution vs ask distribution: True
avg by time: bid distribution vs ask distribution: True
bid distributions: avg by count vs avg by time: True
ask distributions: avg by count vs avg by time: True

EURUSD000TOM
avg by count bid cdf: [0.7566593082278572, 0.8164609136654188, 0.8515579438879834, 0.8892790945230801, 0.9250520893391291, 0.9361852721243603, 0.9441965924508765, 0.9562664339410916, 0.9779551232097199, 0.9999982399854307]
avg by time bid cdf: [0.7383729137103251, 0.7835571011188988, 0.8260361239874093, 0.8639108760870662, 0.9349326650409671, 0.9443961527458401, 0.950699632876162, 0.9559476313891636, 0.9748238447429851, 0.9999999934147649]
avg by count ask cdf: [0.7761494348260467, 0.8102870032283107, 0.8256998264014876, 0.842143211521867, 0.870442929257285, 0.900555137069672, 0.9205196796924111, 0.9564713996907578, 0.9840188565697975, 0.9999929599386741]
avg by time ask cdf: [0.7344899439422581, 0.7616956257528993, 0.7686744642757696, 0.7793238424291618, 0.8216400690392898, 0.8695424928572438, 0.8848061785357686, 0.9399200200213809, 0.9855268353201604, 0.9999997740886175]
avg by count: bid distribution vs ask distribution: True
avg by time: bid distribution vs ask distribution: True
bid distributions: avg by count vs avg by time: True
ask distributions: avg by count vs avg by time: True
